Workbook
Name Category: Dashboard!$L$13
Name State: Dashboard!$F$13
Name Year: Dashboard!$R$13

Sheet Superstore
A1: Row ID | B1: Order ID | C1: Order Date | D1: Ship Date | E1: Ship Mode | F1: Customer ID | G1: Customer Name | H1: Segment | I1: Country | J1: City | K1: State | L1: Postal Code | M1: Region | N1: Product ID | O1: Category | P1: Sub-Category | Q1: Product Name | R1: Sales | S1: Quantity | T1: Discount | U1: Profit | V1: Profit_Margin | W1: Order_month | X1: Order_year | AA1: total sales | AC1: total profit | AE1: profit margin | AG1: average discount | AJ1: Sub-Category | AK1: Total Profit
A2: 1 | B2: CA-2013-152156 | C2: 41587 | D2: 41590 | E2: Second Class | F2: CG-12520 | G2: Claire Gute | H2: Consumer | I2: United States | J2: Henderson | K2: Kentucky | L2: 42420 | M2: South | N2: FUR-BO-10001798 | O2: Furniture | P2: Bookcases | Q2: Bush Somerset Collection Bookcase | R2: 261.96 | S2: 2 | T2: 0 | U2: 41.9136 | V2: =Superstore[[#This Row],[Profit]]/Superstore[[#This Row],[Sales]] -> 0.16 | W2: =TEXT(Superstore[[#This Row],[Order Date]],"mmm-yyyy") -> Nov-2013 | X2: =YEAR(Superstore[[#This Row],[Order Date]]) -> 2013 | AA2: =SUM(Superstore[Sales]) -> 2297200.9 | AC2: =SUM(U:U) -> 286397.02 | AE2: =AC2/AA2 -> 0.12467217 | AG2: =AVERAGE(Superstore[Discount]) -> 0.15620272 | AJ2: {=_xlfn.UNIQUE(Superstore[Sub-Category])} -> Bookcases | AK2: =SUMIF(Superstore[Sub-Category],AJ2,Superstore[Profit]) -> -3472.556
A3: 2 | B3: CA-2013-152156 | C3: 41587 | D3: 41590 | E3: Second Class | F3: CG-12520 | G3: Claire Gute | H3: Consumer | I3: United States | J3: Henderson | K3: Kentucky | L3: 42420 | M3: South | N3: FUR-CH-10000454 | O3: Furniture | P3: Chairs | Q3: Hon Deluxe Fabric Upholstered Stacking Chairs, Rounded Back | R3: 731.94 | S3: 3 | T3: 0 | U3: 219.582 | V3: =Superstore[[#This Row],[Profit]]/Superstore[[#This Row],[Sales]] -> 0.3 | W3: =TEXT(Superstore[[#This Row],[Order Date]],"mmm-yyyy") -> Nov-2013 | X3: =YEAR(Superstore[[#This Row],[Order Date]]) -> 2013 | AJ3: Chairs | AK3: =SUMIF(Superstore[Sub-Category],AJ3,Superstore[Profit]) -> 26590.166
A4: 3 | B4: CA-2013-138688 | C4: 41438 | D4: 41442 | E4: Second Class | F4: DV-13045 | G4: Darrin Van Huff | H4: Corporate | I4: United States | J4: Los Angeles | K4: California | L4: 90036 | M4: West | N4: OFF-LA-10000240 | O4: Office Supplies | P4: Labels | Q4: Self-Adhesive Address Labels for Typewriters by Universal | R4: 14.62 | S4: 2 | T4: 0 | U4: 6.8714 | V4: =Superstore[[#This Row],[Profit]]/Superstore[[#This Row],[Sales]] -> 0.47 | W4: =TEXT(Superstore[[#This Row],[Order Date]],"mmm-yyyy") -> Jun-2013 | X4: =YEAR(Superstore[[#This Row],[Order Date]]) -> 2013 | AJ4: Labels | AK4: =SUMIF(Superstore[Sub-Category],AJ4,Superstore[Profit]) -> 5546.254
A5: 4 | B5: US-2012-108966 | C5: 41193 | D5: 41200 | E5: Standard Class | F5: SO-20335 | G5: Sean O'Donnell | H5: Consumer | I5: United States | J5: Fort Lauderdale | K5: Florida | L5: 33311 | M5: South | N5: FUR-TA-10000577 | O5: Furniture | P5: Tables | Q5: Bretford CR4500 Series Slim Rectangular Table | R5: 957.5775 | S5: 5 | T5: 0.45 | U5: -383.031 | V5: =Superstore[[#This Row],[Profit]]/Superstore[[#This Row],[Sales]] -> -0.4 | W5: =TEXT(Superstore[[#This Row],[Order Date]],"mmm-yyyy") -> Oct-2012 | X5: =YEAR(Superstore[[#This Row],[Order Date]]) -> 2012 | AJ5: Tables | AK5: =SUMIF(Superstore[Sub-Category],AJ5,Superstore[Profit]) -> -17725.481
A6: 5 | B6: US-2012-108966 | C6: 41193 | D6: 41200 | E6: Standard Class | F6: SO-20335 | G6: Sean O'Donnell | H6: Consumer | I6: United States | J6: Fort Lauderdale | K6: Florida | L6: 33311 | M6: South | N6: OFF-ST-10000760 | O6: Office Supplies | P6: Storage | Q6: Eldon Fold 'N Roll Cart System | R6: 22.368 | S6: 2 | T6: 0.2 | U6: 2.5164 | V6: =Superstore[[#This Row],[Profit]]/Superstore[[#This Row],[Sales]] -> 0.1125 | W6: =TEXT(Superstore[[#This Row],[Order Date]],"mmm-yyyy") -> Oct-2012 | X6: =YEAR(Superstore[[#This Row],[Order Date]]) -> 2012 | AJ6: Storage | AK6: =SUMIF(Superstore[Sub-Category],AJ6,Superstore[Profit]) -> 21278.826
A7: 6 | B7: CA-2011-115812 | C7: 40703 | D7: 40708 | E7: Standard Class | F7: BH-11710 | G7: Brosina Hoffman | H7: Consumer | I7: United States | J7: Los Angeles | K7: California | L7: 90032 | M7: West | N7: FUR-FU-10001487 | O7: Furniture | P7: Furnishings | Q7: Eldon Expressions Wood and Plastic Desk Accessories, Cherry Wood | R7: 48.86 | S7: 7 | T7: 0 | U7: 14.1694 | V7: =Superstore[[#This Row],[Profit]]/Superstore[[#This Row],[Sales]] -> 0.29 | W7: =TEXT(Superstore[[#This Row],[Order Date]],"mmm-yyyy") -> Jun-2011 | X7: =YEAR(Superstore[[#This Row],[Order Date]]) -> 2011 | AJ7: Furnishings | AK7: =SUMIF(Superstore[Sub-Category],AJ7,Superstore[Profit]) -> 13059.144
A8: 7 | B8: CA-2011-115812 | C8: 40703 | D8: 40708 | E8: Standard Class | F8: BH-11710 | G8: Brosina Hoffman | H8: Consumer | I8: United States | J8: Los Angeles | K8: California | L8: 90032 | M8: West | N8: OFF-AR-10002833 | O8: Office Supplies | P8: Art | Q8: Newell 322 | R8: 7.28 | S8: 4 | T8: 0 | U8: 1.9656 | V8: =Superstore[[#This Row],[Profit]]/Superstore[[#This Row],[Sales]] -> 0.27 | W8: =TEXT(Superstore[[#This Row],[Order Date]],"mmm-yyyy") -> Jun-2011 | X8: =YEAR(Superstore[[#This Row],[Order Date]]) -> 2011 | AJ8: Art | AK8: =SUMIF(Superstore[Sub-Category],AJ8,Superstore[Profit]) -> 6527.787
A9: 8 | B9: CA-2011-115812 | C9: 40703 | D9: 40708 | E9: Standard Class | F9: BH-11710 | G9: Brosina Hoffman | H9: Consumer | I9: United States | J9: Los Angeles | K9: California | L9: 90032 | M9: West | N9: TEC-PH-10002275 | O9: Technology | P9: Phones | Q9: Mitel 5320 IP Phone VoIP phone | R9: 907.152 | S9: 6 | T9: 0.2 | U9: 90.7152 | V9: =Superstore[[#This Row],[Profit]]/Superstore[[#This Row],[Sales]] -> 0.1 | W9: =TEXT(Superstore[[#This Row],[Order Date]],"mmm-yyyy") -> Jun-2011 | X9: =YEAR(Superstore[[#This Row],[Order Date]]) -> 2011 | AJ9: Phones | AK9: =SUMIF(Superstore[Sub-Category],AJ9,Superstore[Profit]) -> 44515.731
A10: 9 | B10: CA-2011-115812 | C10: 40703 | D10: 40708 | E10: Standard Class | F10: BH-11710 | G10: Brosina Hoffman | H10: Consumer | I10: United States | J10: Los Angeles | K10: California | L10: 90032 | M10: West | N10: OFF-BI-10003910 | O10: Office Supplies | P10: Binders | Q10: DXL Angle-View Binders with Locking Rings by Samsill | R10: 18.504 | S10: 3 | T10: 0.2 | U10: 5.7825 | V10: =Superstore[[#This Row],[Profit]]/Superstore[[#This Row],[Sales]] -> 0.3125 | W10: =TEXT(Superstore[[#This Row],[Order Date]],"mmm-yyyy") -> Jun-2011 | X10: =YEAR(Superstore[[#This Row],[Order Date]]) -> 2011 | AJ10: Binders | AK10: =SUMIF(Superstore[Sub-Category],AJ10,Superstore[Profit]) -> 30221.763
A11: 10 | B11: CA-2011-115812 | C11: 40703 | D11: 40708 | E11: Standard Class | F11: BH-11710 | G11: Brosina Hoffman | H11: Consumer | I11: United States | J11: Los Angeles | K11: California | L11: 90032 | M11: West | N11: OFF-AP-10002892 | O11: Office Supplies | P11: Appliances | Q11: Belkin F5C206VTEL 6 Outlet Surge | R11: 114.9 | S11: 5 | T11: 0 | U11: 34.47 | V11: =Superstore[[#This Row],[Profit]]/Superstore[[#This Row],[Sales]] -> 0.3 | W11: =TEXT(Superstore[[#This Row],[Order Date]],"mmm-yyyy") -> Jun-2011 | X11: =YEAR(Superstore[[#This Row],[Order Date]]) -> 2011 | AJ11: Appliances | AK11: =SUMIF(Superstore[Sub-Category],AJ11,Superstore[Profit]) -> 18138.005
A12: 11 | B12: CA-2011-115812 | C12: 40703 | D12: 40708 | E12: Standard Class | F12: BH-11710 | G12: Brosina Hoffman | H12: Consumer | I12: United States | J12: Los Angeles | K12: California | L12: 90032 | M12: West | N12: FUR-TA-10001539 | O12: Furniture | P12: Tables | Q12: Chromcraft Rectangular Conference Tables | R12: 1706.184 | S12: 9 | T12: 0.2 | U12: 85.3092 | V12: =Superstore[[#This Row],[Profit]]/Superstore[[#This Row],[Sales]] -> 0.05 | W12: =TEXT(Superstore[[#This Row],[Order Date]],"mmm-yyyy") -> Jun-2011 | X12: =YEAR(Superstore[[#This Row],[Order Date]]) -> 2011 | AJ12: Paper | AK12: =SUMIF(Superstore[Sub-Category],AJ12,Superstore[Profit]) -> 34053.569
A13: 12 | B13: CA-2011-115812 | C13: 40703 | D13: 40708 | E13: Standard Class | F13: BH-11710 | G13: Brosina Hoffman | H13: Consumer | I13: United States | J13: Los Angeles | K13: California | L13: 90032 | M13: West | N13: TEC-PH-10002033 | O13: Technology | P13: Phones | Q13: Konftel 250 Conference?phone?- Charcoal black | R13: 911.424 | S13: 4 | T13: 0.2 | U13: 68.3568 | V13: =Superstore[[#This Row],[Profit]]/Superstore[[#This Row],[Sales]] -> 0.075 | W13: =TEXT(Superstore[[#This Row],[Order Date]],"mmm-yyyy") -> Jun-2011 | X13: =YEAR(Superstore[[#This Row],[Order Date]]) -> 2011 | AJ13: Accessories | AK13: =SUMIF(Superstore[Sub-Category],AJ13,Superstore[Profit]) -> 41936.636
A14: 13 | B14: CA-2014-114412 | C14: 41745 | D14: 41750 | E14: Standard Class | F14: AA-10480 | G14: Andrew Allen | H14: Consumer | I14: United States | J14: Concord | K14: North Carolina | L14: 28027 | M14: South | N14: OFF-PA-10002365 | O14: Office Supplies | P14: Paper | Q14: Xerox 1967 | R14: 15.552 | S14: 3 | T14: 0.2 | U14: 5.4432 | V14: =Superstore[[#This Row],[Profit]]/Superstore[[#This Row],[Sales]] -> 0.35 | W14: =TEXT(Superstore[[#This Row],[Order Date]],"mmm-yyyy") -> Apr-2014 | X14: =YEAR(Superstore[[#This Row],[Order Date]]) -> 2014 | AJ14: Envelopes | AK14: =SUMIF(Superstore[Sub-Category],AJ14,Superstore[Profit]) -> 6964.1767
... A18: 17 | B18: CA-2011-105893 | C18: 40858 | D18: 40865 | E18: Standard Class | F18: PK-19075 | G18: Pete Kriz | H18: Consumer | I18: United States | J18: Madison | K18: Wisconsin | L18: 53711 | M18: Central | N18: OFF-ST-10004186 | O18: Office Supplies | P18: Storage | Q18: Stur-D-Stor Shelving, Vertical 5-Shelf: 72"H x 36"W x 18 1/2"D | R18: 665.88 | S18: 6 | T18: 0 | U18: 13.3176 | V18: =Superstore[[#This Row],[Profit]]/Superstore[[#This Row],[Sales]] -> 0.02 | W18: =TEXT(Superstore[[#This Row],[Order Date]],"mmm-yyyy") -> Nov-2011 | X18: =YEAR(Superstore[[#This Row],[Order Date]]) -> 2011 | AJ18: Copiers | AK18: =SUMIF(Superstore[Sub-Category],AJ18,Superstore[Profit]) -> 55617.825
A19: 18 | B19: CA-2011-167164 | C19: 40676 | D19: 40678 | E19: Second Class | F19: AG-10270 | G19: Alejandro Grove | H19: Consumer | I19: United States | J19: West Jordan | K19: Utah | L19: 84084 | M19: West | N19: OFF-ST-10000107 | O19: Office Supplies | P19: Storage | Q19: Fellowes Super Stor/Drawer | R19: 55.5 | S19: 2 | T19: 0 | U19: 9.99 | V19: =Superstore[[#This Row],[Profit]]/Superstore[[#This Row],[Sales]] -> 0.18 | W19: =TEXT(Superstore[[#This Row],[Order Date]],"mmm-yyyy") -> May-2011 | X19: =YEAR(Superstore[[#This Row],[Order Date]]) -> 2011
A20: 19 | B20: CA-2011-143336 | C20: 40782 | D20: 40787 | E20: Second Class | F20: ZD-21925 | G20: Zuschuss Donatelli | H20: Consumer | I20: United States | J20: San Francisco | K20: California | L20: 94109 | M20: West | N20: OFF-AR-10003056 | O20: Office Supplies | P20: Art | Q20: Newell 341 | R20: 8.56 | S20: 2 | T20: 0 | U20: 2.4824 | V20: =Superstore[[#This Row],[Profit]]/Superstore[[#This Row],[Sales]] -> 0.29 | W20: =TEXT(Superstore[[#This Row],[Order Date]],"mmm-yyyy") -> Aug-2011 | X20: =YEAR(Superstore[[#This Row],[Order Date]]) -> 2011 | AJ20: Sub-Category | AK20: Total Profit
A21: 20 | B21: CA-2011-143336 | C21: 40782 | D21: 40787 | E21: Second Class | F21: ZD-21925 | G21: Zuschuss Donatelli | H21: Consumer | I21: United States | J21: San Francisco | K21: California | L21: 94109 | M21: West | N21: TEC-PH-10001949 | O21: Technology | P21: Phones | Q21: Cisco SPA 501G IP Phone | R21: 213.48 | S21: 3 | T21: 0.2 | U21: 16.011 | V21: =Superstore[[#This Row],[Profit]]/Superstore[[#This Row],[Sales]] -> 0.075 | W21: =TEXT(Superstore[[#This Row],[Order Date]],"mmm-yyyy") -> Aug-2011 | X21: =YEAR(Superstore[[#This Row],[Order Date]]) -> 2011 | AJ21: {=_xlfn._xlws.SORT(AJ2:AK18,2,-1)} -> Copiers | AK21: 55617.825
A22: 21 | B22: CA-2011-143336 | C22: 40782 | D22: 40787 | E22: Second Class | F22: ZD-21925 | G22: Zuschuss Donatelli | H22: Consumer | I22: United States | J22: San Francisco | K22: California | L22: 94109 | M22: West | N22: OFF-BI-10002215 | O22: Office Supplies | P22: Binders | Q22: Wilson Jones Hanging View Binder, White, 1" | R22: 22.72 | S22: 4 | T22: 0.2 | U22: 7.384 | V22: =Superstore[[#This Row],[Profit]]/Superstore[[#This Row],[Sales]] -> 0.325 | W22: =TEXT(Superstore[[#This Row],[Order Date]],"mmm-yyyy") -> Aug-2011 | X22: =YEAR(Superstore[[#This Row],[Order Date]]) -> 2011 | AJ22: Phones | AK22: 44515.731
A23: 22 | B23: CA-2013-137330 | C23: 41618 | D23: 41622 | E23: Standard Class | F23: KB-16585 | G23: Ken Black | H23: Corporate | I23: United States | J23: Fremont | K23: Nebraska | L23: 68025 | M23: Central | N23: OFF-AR-10000246 | O23: Office Supplies | P23: Art | Q23: Newell 318 | R23: 19.46 | S23: 7 | T23: 0 | U23: 5.0596 | V23: =Superstore[[#This Row],[Profit]]/Superstore[[#This Row],[Sales]] -> 0.26 | W23: =TEXT(Superstore[[#This Row],[Order Date]],"mmm-yyyy") -> Dec-2013 | X23: =YEAR(Superstore[[#This Row],[Order Date]]) -> 2013 | AJ23: Accessories | AK23: 41936.636
A24: 23 | B24: CA-2013-137330 | C24: 41618 | D24: 41622 | E24: Standard Class | F24: KB-16585 | G24: Ken Black | H24: Corporate | I24: United States | J24: Fremont | K24: Nebraska | L24: 68025 | M24: Central | N24: OFF-AP-10001492 | O24: Office Supplies | P24: Appliances | Q24: Acco Six-Outlet Power Strip, 4' Cord Length | R24: 60.34 | S24: 7 | T24: 0 | U24: 15.6884 | V24: =Superstore[[#This Row],[Profit]]/Superstore[[#This Row],[Sales]] -> 0.26 | W24: =TEXT(Superstore[[#This Row],[Order Date]],"mmm-yyyy") -> Dec-2013 | X24: =YEAR(Superstore[[#This Row],[Order Date]]) -> 2013 | AJ24: Paper | AK24: 34053.569
A25: 24 | B25: US-2014-156909 | C25: 41837 | D25: 41839 | E25: Second Class | F25: SF-20065 | G25: Sandra Flanagan | H25: Consumer | I25: United States | J25: Philadelphia | K25: Pennsylvania | L25: 19140 | M25: East | N25: FUR-CH-10002774 | O25: Furniture | P25: Chairs | Q25: Global Deluxe Stacking Chair, Gray | R25: 71.372 | S25: 2 | T25: 0.3 | U25: -1.0196 | V25: =Superstore[[#This Row],[Profit]]/Superstore[[#This Row],[Sales]] -> -0.014285714 | W25: =TEXT(Superstore[[#This Row],[Order Date]],"mmm-yyyy") -> Jul-2014 | X25: =YEAR(Superstore[[#This Row],[Order Date]]) -> 2014 | AJ25: Binders | AK25: 30221.763
A26: 25 | B26: CA-2012-106320 | C26: 41177 | D26: 41182 | E26: Standard Class | F26: EB-13870 | G26: Emily Burns | H26: Consumer | I26: United States | J26: Orem | K26: Utah | L26: 84057 | M26: West | N26: FUR-TA-10000577 | O26: Furniture | P26: Tables | Q26: Bretford CR4500 Series Slim Rectangular Table | R26: 1044.63 | S26: 3 | T26: 0 | U26: 240.2649 | V26: =Superstore[[#This Row],[Profit]]/Superstore[[#This Row],[Sales]] -> 0.23 | W26: =TEXT(Superstore[[#This Row],[Order Date]],"mmm-yyyy") -> Sep-2012 | X26: =YEAR(Superstore[[#This Row],[Order Date]]) -> 2012 | AJ26: Chairs | AK26: 26590.166
A27: 26 | B27: CA-2013-121755 | C27: 41290 | D27: 41294 | E27: Second Class | F27: EH-13945 | G27: Eric Hoffmann | H27: Consumer | I27: United States | J27: Los Angeles | K27: California | L27: 90049 | M27: West | N27: OFF-BI-10001634 | O27: Office Supplies | P27: Binders | Q27: Wilson Jones Active Use Binders | R27: 11.648 | S27: 2 | T27: 0.2 | U27: 4.2224 | V27: =Superstore[[#This Row],[Profit]]/Superstore[[#This Row],[Sales]] -> 0.3625 | W27: =TEXT(Superstore[[#This Row],[Order Date]],"mmm-yyyy") -> Jan-2013 | X27: =YEAR(Superstore[[#This Row],[Order Date]]) -> 2013 | AJ27: Storage | AK27: 21278.826
A28: 27 | B28: CA-2013-121755 | C28: 41290 | D28: 41294 | E28: Second Class | F28: EH-13945 | G28: Eric Hoffmann | H28: Consumer | I28: United States | J28: Los Angeles | K28: California | L28: 90049 | M28: West | N28: TEC-AC-10003027 | O28: Technology | P28: Accessories | Q28: Imation?8GB Mini TravelDrive USB 2.0?Flash Drive | R28: 90.57 | S28: 3 | T28: 0 | U28: 11.7741 | V28: =Superstore[[#This Row],[Profit]]/Superstore[[#This Row],[Sales]] -> 0.13 | W28: =TEXT(Superstore[[#This Row],[Order Date]],"mmm-yyyy") -> Jan-2013 | X28: =YEAR(Superstore[[#This Row],[Order Date]]) -> 2013 | AJ28: Appliances | AK28: 18138.005
A29: 28 | B29: US-2012-150630 | C29: 41169 | D29: 41173 | E29: Standard Class | F29: TB-21520 | G29: Tracy Blumstein | H29: Consumer | I29: United States | J29: Philadelphia | K29: Pennsylvania | L29: 19140 | M29: East | N29: FUR-BO-10004834 | O29: Furniture | P29: Bookcases | Q29: Riverside Palais Royal Lawyers Bookcase, Royale Cherry Finish | R29: 3083.43 | S29: 7 | T29: 0.5 | U29: -1665.0522 | V29: =Superstore[[#This Row],[Profit]]/Superstore[[#This Row],[Sales]] -> -0.54 | W29: =TEXT(Superstore[[#This Row],[Order Date]],"mmm-yyyy") -> Sep-2012 | X29: =YEAR(Superstore[[#This Row],[Order Date]]) -> 2012 | AJ29: Furnishings | AK29: 13059.144
A30: 29 | B30: US-2012-150630 | C30: 41169 | D30: 41173 | E30: Standard Class | F30: TB-21520 | G30: Tracy Blumstein | H30: Consumer | I30: United States | J30: Philadelphia | K30: Pennsylvania | L30: 19140 | M30: East | N30: OFF-BI-10000474 | O30: Office Supplies | P30: Binders | Q30: Avery Recycled Flexi-View Covers for Binding Systems | R30: 9.618 | S30: 2 | T30: 0.7 | U30: -7.0532 | V30: =Superstore[[#This Row],[Profit]]/Superstore[[#This Row],[Sales]] -> -0.73333333 | W30: =TEXT(Superstore[[#This Row],[Order Date]],"mmm-yyyy") -> Sep-2012 | X30: =YEAR(Superstore[[#This Row],[Order Date]]) -> 2012 | AJ30: Envelopes | AK30: 6964.1767
A31: 30 | B31: US-2012-150630 | C31: 41169 | D31: 41173 | E31: Standard Class | F31: TB-21520 | G31: Tracy Blumstein | H31: Consumer | I31: United States | J31: Philadelphia | K31: Pennsylvania | L31: 19140 | M31: East | N31: FUR-FU-10004848 | O31: Furniture | P31: Furnishings | Q31: Howard Miller 13-3/4" Diameter Brushed Chrome Round Wall Clock | R31: 124.2 | S31: 3 | T31: 0.2 | U31: 15.525 | V31: =Superstore[[#This Row],[Profit]]/Superstore[[#This Row],[Sales]] -> 0.125 | W31: =TEXT(Superstore[[#This Row],[Order Date]],"mmm-yyyy") -> Sep-2012 | X31: =YEAR(Superstore[[#This Row],[Order Date]]) -> 2012 | AJ31: Art | AK31: 6527.787
A32: 31 | B32: US-2012-150630 | C32: 41169 | D32: 41173 | E32: Standard Class | F32: TB-21520 | G32: Tracy Blumstein | H32: Consumer | I32: United States | J32: Philadelphia | K32: Pennsylvania | L32: 19140 | M32: East | N32: OFF-EN-10001509 | O32: Office Supplies | P32: Envelopes | Q32: Poly String Tie Envelopes | R32: 3.264 | S32: 2 | T32: 0.2 | U32: 1.1016 | V32: =Superstore[[#This Row],[Profit]]/Superstore[[#This Row],[Sales]] -> 0.3375 | W32: =TEXT(Superstore[[#This Row],[Order Date]],"mmm-yyyy") -> Sep-2012 | X32: =YEAR(Superstore[[#This Row],[Order Date]]) -> 2012 | AJ32: Labels | AK32: 5546.254
A33: 32 | B33: US-2012-150630 | C33: 41169 | D33: 41173 | E33: Standard Class | F33: TB-21520 | G33: Tracy Blumstein | H33: Consumer | I33: United States | J33: Philadelphia | K33: Pennsylvania | L33: 19140 | M33: East | N33: OFF-AR-10004042 | O33: Office Supplies | P33: Art | Q33: BOSTON Model 1800 Electric Pencil Sharpeners, Putty/Woodgrain | R33: 86.304 | S33: 6 | T33: 0.2 | U33: 9.7092 | V33: =Superstore[[#This Row],[Profit]]/Superstore[[#This Row],[Sales]] -> 0.1125 | W33: =TEXT(Superstore[[#This Row],[Order Date]],"mmm-yyyy") -> Sep-2012 | X33: =YEAR(Superstore[[#This Row],[Order Date]]) -> 2012 | AJ33: Machines | AK33: 3384.7569
... A37: 36 | B37: CA-2013-117590 | C37: 41617 | D37: 41619 | E37: First Class | F37: GH-14485 | G37: Gene Hale | H37: Corporate | I37: United States | J37: Richardson | K37: Texas | L37: 75080 | M37: Central | N37: TEC-PH-10004977 | O37: Technology | P37: Phones | Q37: GE 30524EE4 | R37: 1097.544 | S37: 7 | T37: 0.2 | U37: 123.4737 | V37: =Superstore[[#This Row],[Profit]]/Superstore[[#This Row],[Sales]] -> 0.1125 | W37: =TEXT(Superstore[[#This Row],[Order Date]],"mmm-yyyy") -> Dec-2013 | X37: =YEAR(Superstore[[#This Row],[Order Date]]) -> 2013 | AJ37: Tables | AK37: -17725.481
A38: 37 | B38: CA-2013-117590 | C38: 41617 | D38: 41619 | E38: First Class | F38: GH-14485 | G38: Gene Hale | H38: Corporate | I38: United States | J38: Richardson | K38: Texas | L38: 75080 | M38: Central | N38: FUR-FU-10003664 | O38: Furniture | P38: Furnishings | Q38: Electrix Architect's Clamp-On Swing Arm Lamp, Black | R38: 190.92 | S38: 5 | T38: 0.6 | U38: -147.963 | V38: =Superstore[[#This Row],[Profit]]/Superstore[[#This Row],[Sales]] -> -0.775 | W38: =TEXT(Superstore[[#This Row],[Order Date]],"mmm-yyyy") -> Dec-2013 | X38: =YEAR(Superstore[[#This Row],[Order Date]]) -> 2013
A39: 38 | B39: CA-2012-117415 | C39: 41270 | D39: 41274 | E39: Standard Class | F39: SN-20710 | G39: Steve Nguyen | H39: Home Office | I39: United States | J39: Houston | K39: Texas | L39: 77041 | M39: Central | N39: OFF-EN-10002986 | O39: Office Supplies | P39: Envelopes | Q39: #10-4 1/8" x 9 1/2" Premium Diagonal Seam Envelopes | R39: 113.328 | S39: 9 | T39: 0.2 | U39: 35.415 | V39: =Superstore[[#This Row],[Profit]]/Superstore[[#This Row],[Sales]] -> 0.3125 | W39: =TEXT(Superstore[[#This Row],[Order Date]],"mmm-yyyy") -> Dec-2012 | X39: =YEAR(Superstore[[#This Row],[Order Date]]) -> 2012
A40: 39 | B40: CA-2012-117415 | C40: 41270 | D40: 41274 | E40: Standard Class | F40: SN-20710 | G40: Steve Nguyen | H40: Home Office | I40: United States | J40: Houston | K40: Texas | L40: 77041 | M40: Central | N40: FUR-BO-10002545 | O40: Furniture | P40: Bookcases | Q40: Atlantic Metals Mobile 3-Shelf Bookcases, Custom Colors | R40: 532.3992 | S40: 3 | T40: 0.32 | U40: -46.9764 | V40: =Superstore[[#This Row],[Profit]]/Superstore[[#This Row],[Sales]] -> -0.088235294 | W40: =TEXT(Superstore[[#This Row],[Order Date]],"mmm-yyyy") -> Dec-2012 | X40: =YEAR(Superstore[[#This Row],[Order Date]]) -> 2012
A41: 40 | B41: CA-2012-117415 | C41: 41270 | D41: 41274 | E41: Standard Class | F41: SN-20710 | G41: Steve Nguyen | H41: Home Office | I41: United States | J41: Houston | K41: Texas | L41: 77041 | M41: Central | N41: FUR-CH-10004218 | O41: Furniture | P41: Chairs | Q41: Global Fabric Manager's Chair, Dark Gray | R41: 212.058 | S41: 3 | T41: 0.3 | U41: -15.147 | V41: =Superstore[[#This Row],[Profit]]/Superstore[[#This Row],[Sales]] -> -0.071428571 | W41: =TEXT(Superstore[[#This Row],[Order Date]],"mmm-yyyy") -> Dec-2012 | X41: =YEAR(Superstore[[#This Row],[Order Date]]) -> 2012
A42: 41 | B42: CA-2012-117415 | C42: 41270 | D42: 41274 | E42: Standard Class | F42: SN-20710 | G42: Steve Nguyen | H42: Home Office | I42: United States | J42: Houston | K42: Texas | L42: 77041 | M42: Central | N42: TEC-PH-10000486 | O42: Technology | P42: Phones | Q42: Plantronics HL10 Handset Lifter | R42: 371.168 | S42: 4 | T42: 0.2 | U42: 41.7564 | V42: =Superstore[[#This Row],[Profit]]/Superstore[[#This Row],[Sales]] -> 0.1125 | W42: =TEXT(Superstore[[#This Row],[Order Date]],"mmm-yyyy") -> Dec-2012 | X42: =YEAR(Superstore[[#This Row],[Order Date]]) -> 2012
A43: 42 | B43: CA-2014-120999 | C43: 41893 | D43: 41898 | E43: Standard Class | F43: LC-16930 | G43: Linda Cazamias | H43: Corporate | I43: United States | J43: Naperville | K43: Illinois | L43: 60540 | M43: Central | N43: TEC-PH-10004093 | O43: Technology | P43: Phones | Q43: Panasonic Kx-TS550 | R43: 147.168 | S43: 4 | T43: 0.2 | U43: 16.5564 | V43: =Superstore[[#This Row],[Profit]]/Superstore[[#This Row],[Sales]] -> 0.1125 | W43: =TEXT(Superstore[[#This Row],[Order Date]],"mmm-yyyy") -> Sep-2014 | X43: =YEAR(Superstore[[#This Row],[Order Date]]) -> 2014
A44: 43 | B44: CA-2013-101343 | C44: 41473 | D44: 41478 | E44: Standard Class | F44: RA-19885 | G44: Ruben Ausman | H44: Corporate | I44: United States | J44: Los Angeles | K44: California | L44: 90049 | M44: West | N44: OFF-ST-10003479 | O44: Office Supplies | P44: Storage | Q44: Eldon Base for stackable storage shelf, platinum | R44: 77.88 | S44: 2 | T44: 0 | U44: 3.894 | V44: =Superstore[[#This Row],[Profit]]/Superstore[[#This Row],[Sales]] -> 0.05 | W44: =TEXT(Superstore[[#This Row],[Order Date]],"mmm-yyyy") -> Jul-2013 | X44: =YEAR(Superstore[[#This Row],[Order Date]]) -> 2013
A45: 44 | B45: CA-2014-139619 | C45: 41902 | D45: 41906 | E45: Standard Class | F45: ES-14080 | G45: Erin Smith | H45: Corporate | I45: United States | J45: Melbourne | K45: Florida | L45: 32935 | M45: South | N45: OFF-ST-10003282 | O45: Office Supplies | P45: Storage | Q45: Advantus 10-Drawer Portable Organizer, Chrome Metal Frame, Smoke Drawers | R45: 95.616 | S45: 2 | T45: 0.2 | U45: 9.5616 | V45: =Superstore[[#This Row],[Profit]]/Superstore[[#This Row],[Sales]] -> 0.1 | W45: =TEXT(Superstore[[#This Row],[Order Date]],"mmm-yyyy") -> Sep-2014 | X45: =YEAR(Superstore[[#This Row],[Order Date]]) -> 2014
A46: 45 | B46: CA-2013-118255 | C46: 41345 | D46: 41347 | E46: First Class | F46: ON-18715 | G46: Odella Nelson | H46: Corporate | I46: United States | J46: Eagan | K46: Minnesota | L46: 55122 | M46: Central | N46: TEC-AC-10000171 | O46: Technology | P46: Accessories | Q46: Verbatim 25 GB 6x Blu-ray Single Layer Recordable Disc, 25/Pack | R46: 45.98 | S46: 2 | T46: 0 | U46: 19.7714 | V46: =Superstore[[#This Row],[Profit]]/Superstore[[#This Row],[Sales]] -> 0.43 | W46: =TEXT(Superstore[[#This Row],[Order Date]],"mmm-yyyy") -> Mar-2013 | X46: =YEAR(Superstore[[#This Row],[Order Date]]) -> 2013
...

Sheet Dashboard
F12: State | L12: Category | R12: Year
F13: New York | L13: Office Supplies | R13: 2011

Sheet helper
A1: State List | K1: Category List | L1: Year_List | N1: Order Month | O1: total sales | P1: total profit | Q1: Order Month | R1: total sales | S1: total profit | T1: Order Month | U1: total sales | V1: total profit | AC1: Sub-Category | AD1: Discount | AE1: Profit | AF1: Sub-Category | AG1: Discount | AH1: Profit | AI1: Sub-Category | AJ1: Discount | AK1: Profit
A2: {=_xlfn._xlws.SORT(_xlfn.UNIQUE(Superstore[State]))} -> Alabama | E2: Sub-Category | F2: Total Profit | G2: Sub-Category | H2: Total Profit | K2: {=_xlfn._xlws.SORT(_xlfn.UNIQUE(Superstore[Category]))} -> Furniture | L2: {=_xlfn._xlws.SORT(_xlfn.UNIQUE(Superstore[Order_year]))} -> 2011 | N2: {=_xlfn.SORTBY( _xlfn.UNIQUE(Superstore[Order_month]), DATEVALUE("1-" & _xlfn.UNIQUE(Superstore[Order_month])), 1 )} -> Jan-2011 | O2: =SUMIFS(Superstore[Sales],Superstore[Order_month],N2,Superstore[State],State,Superstore[Category],Category,Superstore[Order_year],Year) -> 3.928 | P2: =SUMIFS(Superstore[Profit],Superstore[Order_month],N2,Superstore[State],State,Superstore[Category],Category,Superstore[Order_year],Year) -> 1.3257 | Q2: {=_xlfn._xlws.FILTER(N2:P49,O2:O49<>0)} -> Jan-2011 | R2: 3.928 | S2: 1.3257 | T2: {=_xlfn.ANCHORARRAY(Q2)} -> Jan-2011 | U2: 3.928 | V2: 1.3257 | AC2: {=_xlfn.UNIQUE(Superstore[Sub-Category])} -> Bookcases | AD2: =IFERROR(AVERAGEIFS(Superstore[Discount],Superstore[Sub-Category],$AC2,Superstore[State],State,Superstore[Category],Category,Superstore[Order_year],Year),0) -> 0 | AE2: =IFERROR(AVERAGEIFS(Superstore[Profit],Superstore[Sub-Category],$AC2,Superstore[State],State,Superstore[Category],Category,Superstore[Order_year],Year),0) -> 0 | AF2: {=_xlfn._xlws.FILTER(AC2:AE18,AE2:AE18<>0)} -> Labels | AG2: 0 | AH2: 17.24365 | AI2: {=_xlfn.ANCHORARRAY(AF2)} -> Labels | AJ2: 0 | AK2: 17.24365
A3: Arizona | E3: {=_xlfn.UNIQUE(Superstore[Sub-Category])} -> Bookcases | F3: =SUMIFS(Superstore[Profit],Superstore[Sub-Category],helper!E3,Superstore[State],State,Superstore[Category],Category,Superstore[Order_year],Year) -> 0 | G3: {=_xlfn._xlws.FILTER(E3:F19,F3:F19<>0)} -> Labels | H3: 137.9492 | K3: Office Supplies | L3: 2012 | N3: Feb-2011 | O3: =SUMIFS(Superstore[Sales],Superstore[Order_month],N3,Superstore[State],State,Superstore[Category],Category,Superstore[Order_year],Year) -> 64.96 | P3: =SUMIFS(Superstore[Profit],Superstore[Order_month],N3,Superstore[State],State,Superstore[Category],Category,Superstore[Order_year],Year) -> 9.744 | Q3: Feb-2011 | R3: 64.96 | S3: 9.744 | T3: Feb-2011 | U3: 64.96 | V3: 9.744 | AC3: Chairs | AD3: =IFERROR(AVERAGEIFS(Superstore[Discount],Superstore[Sub-Category],$AC3,Superstore[State],State,Superstore[Category],Category,Superstore[Order_year],Year),0) -> 0 | AE3: =IFERROR(AVERAGEIFS(Superstore[Profit],Superstore[Sub-Category],$AC3,Superstore[State],State,Superstore[Category],Category,Superstore[Order_year],Year),0) -> 0 | AF3: Storage | AG3: 0 | AH3: 63.43646 | AI3: Storage | AJ3: 0 | AK3: 63.43646
A4: Arkansas | E4: Chairs | F4: =SUMIFS(Superstore[Profit],Superstore[Sub-Category],helper!E4,Superstore[State],State,Superstore[Category],Category,Superstore[Order_year],Year) -> 0 | G4: Storage | H4: 634.3646 | K4: Technology | L4: 2013 | N4: Mar-2011 | O4: =SUMIFS(Superstore[Sales],Superstore[Order_month],N4,Superstore[State],State,Superstore[Category],Category,Superstore[Order_year],Year) -> 808.302 | P4: =SUMIFS(Superstore[Profit],Superstore[Order_month],N4,Superstore[State],State,Superstore[Category],Category,Superstore[Order_year],Year) -> 333.3267 | Q4: Mar-2011 | R4: 808.302 | S4: 333.3267 | T4: Mar-2011 | U4: 808.302 | V4: 333.3267 | AC4: Labels | AD4: =IFERROR(AVERAGEIFS(Superstore[Discount],Superstore[Sub-Category],$AC4,Superstore[State],State,Superstore[Category],Category,Superstore[Order_year],Year),0) -> 0 | AE4: =IFERROR(AVERAGEIFS(Superstore[Profit],Superstore[Sub-Category],$AC4,Superstore[State],State,Superstore[Category],Category,Superstore[Order_year],Year),0) -> 17.24365 | AF4: Art | AG4: 0 | AH4: 8.0734667 | AI4: Art | AJ4: 0 | AK4: 8.0734667
A5: California | E5: Labels | F5: =SUMIFS(Superstore[Profit],Superstore[Sub-Category],helper!E5,Superstore[State],State,Superstore[Category],Category,Superstore[Order_year],Year) -> 137.9492 | G5: Art | H5: 121.102 | L5: 2014 | N5: Apr-2011 | O5: =SUMIFS(Superstore[Sales],Superstore[Order_month],N5,Superstore[State],State,Superstore[Category],Category,Superstore[Order_year],Year) -> 313.232 | P5: =SUMIFS(Superstore[Profit],Superstore[Order_month],N5,Superstore[State],State,Superstore[Category],Category,Superstore[Order_year],Year) -> 151.4173 | Q5: Apr-2011 | R5: 313.232 | S5: 151.4173 | T5: Apr-2011 | U5: 313.232 | V5: 151.4173 | AC5: Tables | AD5: =IFERROR(AVERAGEIFS(Superstore[Discount],Superstore[Sub-Category],$AC5,Superstore[State],State,Superstore[Category],Category,Superstore[Order_year],Year),0) -> 0 | AE5: =IFERROR(AVERAGEIFS(Superstore[Profit],Superstore[Sub-Category],$AC5,Superstore[State],State,Superstore[Category],Category,Superstore[Order_year],Year),0) -> 0 | AF5: Binders | AG5: 0.2 | AH5: 37.411286 | AI5: Binders | AJ5: 0.2 | AK5: 37.411286
A6: Colorado | E6: Tables | F6: =SUMIFS(Superstore[Profit],Superstore[Sub-Category],helper!E6,Superstore[State],State,Superstore[Category],Category,Superstore[Order_year],Year) -> 0 | G6: Binders | H6: 1384.2176 | N6: May-2011 | O6: =SUMIFS(Superstore[Sales],Superstore[Order_month],N6,Superstore[State],State,Superstore[Category],Category,Superstore[Order_year],Year) -> 704.624 | P6: =SUMIFS(Superstore[Profit],Superstore[Order_month],N6,Superstore[State],State,Superstore[Category],Category,Superstore[Order_year],Year) -> 228.3138 | Q6: May-2011 | R6: 704.624 | S6: 228.3138 | T6: May-2011 | U6: 704.624 | V6: 228.3138 | AC6: Storage | AD6: =IFERROR(AVERAGEIFS(Superstore[Discount],Superstore[Sub-Category],$AC6,Superstore[State],State,Superstore[Category],Category,Superstore[Order_year],Year),0) -> 0 | AE6: =IFERROR(AVERAGEIFS(Superstore[Profit],Superstore[Sub-Category],$AC6,Superstore[State],State,Superstore[Category],Category,Superstore[Order_year],Year),0) -> 63.43646 | AF6: Appliances | AG6: 0 | AH6: 49.6425 | AI6: Appliances | AJ6: 0 | AK6: 49.6425
A7: Connecticut | E7: Storage | F7: =SUMIFS(Superstore[Profit],Superstore[Sub-Category],helper!E7,Superstore[State],State,Superstore[Category],Category,Superstore[Order_year],Year) -> 634.3646 | G7: Appliances | H7: 595.71 | N7: Jun-2011 | O7: =SUMIFS(Superstore[Sales],Superstore[Order_month],N7,Superstore[State],State,Superstore[Category],Category,Superstore[Order_year],Year) -> 2494.242 | P7: =SUMIFS(Superstore[Profit],Superstore[Order_month],N7,Superstore[State],State,Superstore[Category],Category,Superstore[Order_year],Year) -> 371.0555 | Q7: Jun-2011 | R7: 2494.242 | S7: 371.0555 | T7: Jun-2011 | U7: 2494.242 | V7: 371.0555 | AC7: Furnishings | AD7: =IFERROR(AVERAGEIFS(Superstore[Discount],Superstore[Sub-Category],$AC7,Superstore[State],State,Superstore[Category],Category,Superstore[Order_year],Year),0) -> 0 | AE7: =IFERROR(AVERAGEIFS(Superstore[Profit],Superstore[Sub-Category],$AC7,Superstore[State],State,Superstore[Category],Category,Superstore[Order_year],Year),0) -> 0 | AF7: Paper | AG7: 0 | AH7: 27.829528 | AI7: Paper | AJ7: 0 | AK7: 27.829528
A8: Delaware | E8: Furnishings | F8: =SUMIFS(Superstore[Profit],Superstore[Sub-Category],helper!E8,Superstore[State],State,Superstore[Category],Category,Superstore[Order_year],Year) -> 0 | G8: Paper | H8: 807.0563 | N8: Jul-2011 | O8: =SUMIFS(Superstore[Sales],Superstore[Order_month],N8,Superstore[State],State,Superstore[Category],Category,Superstore[Order_year],Year) -> 170.984 | P8: =SUMIFS(Superstore[Profit],Superstore[Order_month],N8,Superstore[State],State,Superstore[Category],Category,Superstore[Order_year],Year) -> 72.3892 | Q8: Jul-2011 | R8: 170.984 | S8: 72.3892 | T8: Jul-2011 | U8: 170.984 | V8: 72.3892 | AC8: Art | AD8: =IFERROR(AVERAGEIFS(Superstore[Discount],Superstore[Sub-Category],$AC8,Superstore[State],State,Superstore[Category],Category,Superstore[Order_year],Year),0) -> 0 | AE8: =IFERROR(AVERAGEIFS(Superstore[Profit],Superstore[Sub-Category],$AC8,Superstore[State],State,Superstore[Category],Category,Superstore[Order_year],Year),0) -> 8.0734667 | AF8: Envelopes | AG8: 0 | AH8: 32.7806 | AI8: Envelopes | AJ8: 0 | AK8: 32.7806
A9: District of Columbia | E9: Art | F9: =SUMIFS(Superstore[Profit],Superstore[Sub-Category],helper!E9,Superstore[State],State,Superstore[Category],Category,Superstore[Order_year],Year) -> 121.102 | G9: Envelopes | H9: 229.4642 | N9: Aug-2011 | O9: =SUMIFS(Superstore[Sales],Superstore[Order_month],N9,Superstore[State],State,Superstore[Category],Category,Superstore[Order_year],Year) -> 639.432 | P9: =SUMIFS(Superstore[Profit],Superstore[Order_month],N9,Superstore[State],State,Superstore[Category],Category,Superstore[Order_year],Year) -> 116.3134 | Q9: Aug-2011 | R9: 639.432 | S9: 116.3134 | T9: Aug-2011 | U9: 639.432 | V9: 116.3134 | AC9: Phones | AD9: =IFERROR(AVERAGEIFS(Superstore[Discount],Superstore[Sub-Category],$AC9,Superstore[State],State,Superstore[Category],Category,Superstore[Order_year],Year),0) -> 0 | AE9: =IFERROR(AVERAGEIFS(Superstore[Profit],Superstore[Sub-Category],$AC9,Superstore[State],State,Superstore[Category],Category,Superstore[Order_year],Year),0) -> 0 | AF9: Fasteners | AG9: 0 | AH9: 2.0788 | AI9: Fasteners | AJ9: 0 | AK9: 2.0788
A10: Florida | E10: Phones | F10: =SUMIFS(Superstore[Profit],Superstore[Sub-Category],helper!E10,Superstore[State],State,Superstore[Category],Category,Superstore[Order_year],Year) -> 0 | G10: Fasteners | H10: 4.1576 | N10: Sep-2011 | O10: =SUMIFS(Superstore[Sales],Superstore[Order_month],N10,Superstore[State],State,Superstore[Category],Category,Superstore[Order_year],Year) -> 3289.044 | P10: =SUMIFS(Superstore[Profit],Superstore[Order_month],N10,Superstore[State],State,Superstore[Category],Category,Superstore[Order_year],Year) -> 903.2716 | Q10: Sep-2011 | R10: 3289.044 | S10: 903.2716 | T10: Sep-2011 | U10: 3289.044 | V10: 903.2716 | AC10: Binders | AD10: =IFERROR(AVERAGEIFS(Superstore[Discount],Superstore[Sub-Category],$AC10,Superstore[State],State,Superstore[Category],Category,Superstore[Order_year],Year),0) -> 0.2 | AE10: =IFERROR(AVERAGEIFS(Superstore[Profit],Superstore[Sub-Category],$AC10,Superstore[State],State,Superstore[Category],Category,Superstore[Order_year],Year),0) -> 37.411286 | AF10: Supplies | AG10: 0 | AH10: 7.75908 | AI10: Supplies | AJ10: 0 | AK10: 7.75908
A11: Georgia | E11: Binders | F11: =SUMIFS(Superstore[Profit],Superstore[Sub-Category],helper!E11,Superstore[State],State,Superstore[Category],Category,Superstore[Order_year],Year) -> 1384.2176 | G11: Supplies | H11: 38.7954 | N11: Oct-2011 | O11: =SUMIFS(Superstore[Sales],Superstore[Order_month],N11,Superstore[State],State,Superstore[Category],Category,Superstore[Order_year],Year) -> 131.672 | P11: =SUMIFS(Superstore[Profit],Superstore[Order_month],N11,Superstore[State],State,Superstore[Category],Category,Superstore[Order_year],Year) -> 58.5741 | Q11: Oct-2011 | R11: 131.672 | S11: 58.5741 | T11: Oct-2011 | U11: 131.672 | V11: 58.5741 | AC11: Appliances | AD11: =IFERROR(AVERAGEIFS(Superstore[Discount],Superstore[Sub-Category],$AC11,Superstore[State],State,Superstore[Category],Category,Superstore[Order_year],Year),0) -> 0 | AE11: =IFERROR(AVERAGEIFS(Superstore[Profit],Superstore[Sub-Category],$AC11,Superstore[State],State,Superstore[Category],Category,Superstore[Order_year],Year),0) -> 49.6425
A12: Idaho | E12: Appliances | F12: =SUMIFS(Superstore[Profit],Superstore[Sub-Category],helper!E12,Superstore[State],State,Superstore[Category],Category,Superstore[Order_year],Year) -> 595.71 | N12: Nov-2011 | O12: =SUMIFS(Superstore[Sales],Superstore[Order_month],N12,Superstore[State],State,Superstore[Category],Category,Superstore[Order_year],Year) -> 4835.93 | P12: =SUMIFS(Superstore[Profit],Superstore[Order_month],N12,Superstore[State],State,Superstore[Category],Category,Superstore[Order_year],Year) -> 1405.1748 | Q12: Nov-2011 | R12: 4835.93 | S12: 1405.1748 | T12: Nov-2011 | U12: 4835.93 | V12: 1405.1748 | AC12: Paper | AD12: =IFERROR(AVERAGEIFS(Superstore[Discount],Superstore[Sub-Category],$AC12,Superstore[State],State,Superstore[Category],Category,Superstore[Order_year],Year),0) -> 0 | AE12: =IFERROR(AVERAGEIFS(Superstore[Profit],Superstore[Sub-Category],$AC12,Superstore[State],State,Superstore[Category],Category,Superstore[Order_year],Year),0) -> 27.829528
A13: Illinois | E13: Paper | F13: =SUMIFS(Superstore[Profit],Superstore[Sub-Category],helper!E13,Superstore[State],State,Superstore[Category],Category,Superstore[Order_year],Year) -> 807.0563 | N13: Dec-2011 | O13: =SUMIFS(Superstore[Sales],Superstore[Order_month],N13,Superstore[State],State,Superstore[Category],Category,Superstore[Order_year],Year) -> 1103.224 | P13: =SUMIFS(Superstore[Profit],Superstore[Order_month],N13,Superstore[State],State,Superstore[Category],Category,Superstore[Order_year],Year) -> 301.9108 | Q13: Dec-2011 | R13: 1103.224 | S13: 301.9108 | T13: Dec-2011 | U13: 1103.224 | V13: 301.9108 | AC13: Accessories | AD13: =IFERROR(AVERAGEIFS(Superstore[Discount],Superstore[Sub-Category],$AC13,Superstore[State],State,Superstore[Category],Category,Superstore[Order_year],Year),0) -> 0 | AE13: =IFERROR(AVERAGEIFS(Superstore[Profit],Superstore[Sub-Category],$AC13,Superstore[State],State,Superstore[Category],Category,Superstore[Order_year],Year),0) -> 0
A14: Indiana | E14: Accessories | F14: =SUMIFS(Superstore[Profit],Superstore[Sub-Category],helper!E14,Superstore[State],State,Superstore[Category],Category,Superstore[Order_year],Year) -> 0 | N14: Jan-2012 | O14: =SUMIFS(Superstore[Sales],Superstore[Order_month],N14,Superstore[State],State,Superstore[Category],Category,Superstore[Order_year],Year) -> 0 | P14: =SUMIFS(Superstore[Profit],Superstore[Order_month],N14,Superstore[State],State,Superstore[Category],Category,Superstore[Order_year],Year) -> 0 | AC14: Envelopes | AD14: =IFERROR(AVERAGEIFS(Superstore[Discount],Superstore[Sub-Category],$AC14,Superstore[State],State,Superstore[Category],Category,Superstore[Order_year],Year),0) -> 0 | AE14: =IFERROR(AVERAGEIFS(Superstore[Profit],Superstore[Sub-Category],$AC14,Superstore[State],State,Superstore[Category],Category,Superstore[Order_year],Year),0) -> 32.7806
A15: Iowa | E15: Envelopes | F15: =SUMIFS(Superstore[Profit],Superstore[Sub-Category],helper!E15,Superstore[State],State,Superstore[Category],Category,Superstore[Order_year],Year) -> 229.4642 | N15: Feb-2012 | O15: =SUMIFS(Superstore[Sales],Superstore[Order_month],N15,Superstore[State],State,Superstore[Category],Category,Superstore[Order_year],Year) -> 0 | P15: =SUMIFS(Superstore[Profit],Superstore[Order_month],N15,Superstore[State],State,Superstore[Category],Category,Superstore[Order_year],Year) -> 0 | AC15: Fasteners | AD15: =IFERROR(AVERAGEIFS(Superstore[Discount],Superstore[Sub-Category],$AC15,Superstore[State],State,Superstore[Category],Category,Superstore[Order_year],Year),0) -> 0 | AE15: =IFERROR(AVERAGEIFS(Superstore[Profit],Superstore[Sub-Category],$AC15,Superstore[State],State,Superstore[Category],Category,Superstore[Order_year],Year),0) -> 2.0788
A16: Kansas | E16: Fasteners | F16: =SUMIFS(Superstore[Profit],Superstore[Sub-Category],helper!E16,Superstore[State],State,Superstore[Category],Category,Superstore[Order_year],Year) -> 4.1576 | N16: Mar-2012 | O16: =SUMIFS(Superstore[Sales],Superstore[Order_month],N16,Superstore[State],State,Superstore[Category],Category,Superstore[Order_year],Year) -> 0 | P16: =SUMIFS(Superstore[Profit],Superstore[Order_month],N16,Superstore[State],State,Superstore[Category],Category,Superstore[Order_year],Year) -> 0 | AC16: Supplies | AD16: =IFERROR(AVERAGEIFS(Superstore[Discount],Superstore[Sub-Category],$AC16,Superstore[State],State,Superstore[Category],Category,Superstore[Order_year],Year),0) -> 0 | AE16: =IFERROR(AVERAGEIFS(Superstore[Profit],Superstore[Sub-Category],$AC16,Superstore[State],State,Superstore[Category],Category,Superstore[Order_year],Year),0) -> 7.75908
A17: Kentucky | E17: Supplies | F17: =SUMIFS(Superstore[Profit],Superstore[Sub-Category],helper!E17,Superstore[State],State,Superstore[Category],Category,Superstore[Order_year],Year) -> 38.7954 | N17: Apr-2012 | O17: =SUMIFS(Superstore[Sales],Superstore[Order_month],N17,Superstore[State],State,Superstore[Category],Category,Superstore[Order_year],Year) -> 0 | P17: =SUMIFS(Superstore[Profit],Superstore[Order_month],N17,Superstore[State],State,Superstore[Category],Category,Superstore[Order_year],Year) -> 0 | AC17: Machines | AD17: =IFERROR(AVERAGEIFS(Superstore[Discount],Superstore[Sub-Category],$AC17,Superstore[State],State,Superstore[Category],Category,Superstore[Order_year],Year),0) -> 0 | AE17: =IFERROR(AVERAGEIFS(Superstore[Profit],Superstore[Sub-Category],$AC17,Superstore[State],State,Superstore[Category],Category,Superstore[Order_year],Year),0) -> 0
A18: Louisiana | E18: Machines | F18: =SUMIFS(Superstore[Profit],Superstore[Sub-Category],helper!E18,Superstore[State],State,Superstore[Category],Category,Superstore[Order_year],Year) -> 0 | N18: May-2012 | O18: =SUMIFS(Superstore[Sales],Superstore[Order_month],N18,Superstore[State],State,Superstore[Category],Category,Superstore[Order_year],Year) -> 0 | P18: =SUMIFS(Superstore[Profit],Superstore[Order_month],N18,Superstore[State],State,Superstore[Category],Category,Superstore[Order_year],Year) -> 0 | AC18: Copiers | AD18: =IFERROR(AVERAGEIFS(Superstore[Discount],Superstore[Sub-Category],$AC18,Superstore[State],State,Superstore[Category],Category,Superstore[Order_year],Year),0) -> 0 | AE18: =IFERROR(AVERAGEIFS(Superstore[Profit],Superstore[Sub-Category],$AC18,Superstore[State],State,Superstore[Category],Category,Superstore[Order_year],Year),0) -> 0
A19: Maine | E19: Copiers | F19: =SUMIFS(Superstore[Profit],Superstore[Sub-Category],helper!E19,Superstore[State],State,Superstore[Category],Category,Superstore[Order_year],Year) -> 0 | N19: Jun-2012 | O19: =SUMIFS(Superstore[Sales],Superstore[Order_month],N19,Superstore[State],State,Superstore[Category],Category,Superstore[Order_year],Year) -> 0 | P19: =SUMIFS(Superstore[Profit],Superstore[Order_month],N19,Superstore[State],State,Superstore[Category],Category,Superstore[Order_year],Year) -> 0
A20: Maryland | N20: Jul-2012 | O20: =SUMIFS(Superstore[Sales],Superstore[Order_month],N20,Superstore[State],State,Superstore[Category],Category,Superstore[Order_year],Year) -> 0 | P20: =SUMIFS(Superstore[Profit],Superstore[Order_month],N20,Superstore[State],State,Superstore[Category],Category,Superstore[Order_year],Year) -> 0
A21: Massachusetts | N21: Aug-2012 | O21: =SUMIFS(Superstore[Sales],Superstore[Order_month],N21,Superstore[State],State,Superstore[Category],Category,Superstore[Order_year],Year) -> 0 | P21: =SUMIFS(Superstore[Profit],Superstore[Order_month],N21,Superstore[State],State,Superstore[Category],Category,Superstore[Order_year],Year) -> 0
A22: Michigan | N22: Sep-2012 | O22: =SUMIFS(Superstore[Sales],Superstore[Order_month],N22,Superstore[State],State,Superstore[Category],Category,Superstore[Order_year],Year) -> 0 | P22: =SUMIFS(Superstore[Profit],Superstore[Order_month],N22,Superstore[State],State,Superstore[Category],Category,Superstore[Order_year],Year) -> 0
A23: Minnesota | N23: Oct-2012 | O23: =SUMIFS(Superstore[Sales],Superstore[Order_month],N23,Superstore[State],State,Superstore[Category],Category,Superstore[Order_year],Year) -> 0 | P23: =SUMIFS(Superstore[Profit],Superstore[Order_month],N23,Superstore[State],State,Superstore[Category],Category,Superstore[Order_year],Year) -> 0
A24: Mississippi | N24: Nov-2012 | O24: =SUMIFS(Superstore[Sales],Superstore[Order_month],N24,Superstore[State],State,Superstore[Category],Category,Superstore[Order_year],Year) -> 0 | P24: =SUMIFS(Superstore[Profit],Superstore[Order_month],N24,Superstore[State],State,Superstore[Category],Category,Superstore[Order_year],Year) -> 0
A25: Missouri | N25: Dec-2012 | O25: =SUMIFS(Superstore[Sales],Superstore[Order_month],N25,Superstore[State],State,Superstore[Category],Category,Superstore[Order_year],Year) -> 0 | P25: =SUMIFS(Superstore[Profit],Superstore[Order_month],N25,Superstore[State],State,Superstore[Category],Category,Superstore[Order_year],Year) -> 0
A26: Montana | N26: Jan-2013 | O26: =SUMIFS(Superstore[Sales],Superstore[Order_month],N26,Superstore[State],State,Superstore[Category],Category,Superstore[Order_year],Year) -> 0 | P26: =SUMIFS(Superstore[Profit],Superstore[Order_month],N26,Superstore[State],State,Superstore[Category],Category,Superstore[Order_year],Year) -> 0
A27: Nebraska | G27: Sub-Category | H27: Total Profit | N27: Feb-2013 | O27: =SUMIFS(Superstore[Sales],Superstore[Order_month],N27,Superstore[State],State,Superstore[Category],Category,Superstore[Order_year],Year) -> 0 | P27: =SUMIFS(Superstore[Profit],Superstore[Order_month],N27,Superstore[State],State,Superstore[Category],Category,Superstore[Order_year],Year) -> 0
A28: Nevada | G28: {=_xlfn.ANCHORARRAY(G3)} -> Labels | H28: 137.9492 | N28: Mar-2013 | O28: =SUMIFS(Superstore[Sales],Superstore[Order_month],N28,Superstore[State],State,Superstore[Category],Category,Superstore[Order_year],Year) -> 0 | P28: =SUMIFS(Superstore[Profit],Superstore[Order_month],N28,Superstore[State],State,Superstore[Category],Category,Superstore[Order_year],Year) -> 0
A29: New Hampshire | G29: Storage | H29: 634.3646 | N29: Apr-2013 | O29: =SUMIFS(Superstore[Sales],Superstore[Order_month],N29,Superstore[State],State,Superstore[Category],Category,Superstore[Order_year],Year) -> 0 | P29: =SUMIFS(Superstore[Profit],Superstore[Order_month],N29,Superstore[State],State,Superstore[Category],Category,Superstore[Order_year],Year) -> 0
A30: New Jersey | G30: Art | H30: 121.102 | N30: May-2013 | O30: =SUMIFS(Superstore[Sales],Superstore[Order_month],N30,Superstore[State],State,Superstore[Category],Category,Superstore[Order_year],Year) -> 0 | P30: =SUMIFS(Superstore[Profit],Superstore[Order_month],N30,Superstore[State],State,Superstore[Category],Category,Superstore[Order_year],Year) -> 0
A31: New Mexico | G31: Binders | H31: 1384.2176 | N31: Jun-2013 | O31: =SUMIFS(Superstore[Sales],Superstore[Order_month],N31,Superstore[State],State,Superstore[Category],Category,Superstore[Order_year],Year) -> 0 | P31: =SUMIFS(Superstore[Profit],Superstore[Order_month],N31,Superstore[State],State,Superstore[Category],Category,Superstore[Order_year],Year) -> 0
A32: New York | G32: Appliances | H32: 595.71 | N32: Jul-2013 | O32: =SUMIFS(Superstore[Sales],Superstore[Order_month],N32,Superstore[State],State,Superstore[Category],Category,Superstore[Order_year],Year) -> 0 | P32: =SUMIFS(Superstore[Profit],Superstore[Order_month],N32,Superstore[State],State,Superstore[Category],Category,Superstore[Order_year],Year) -> 0
A33: North Carolina | G33: Paper | H33: 807.0563 | N33: Aug-2013 | O33: =SUMIFS(Superstore[Sales],Superstore[Order_month],N33,Superstore[State],State,Superstore[Category],Category,Superstore[Order_year],Year) -> 0 | P33: =SUMIFS(Superstore[Profit],Superstore[Order_month],N33,Superstore[State],State,Superstore[Category],Category,Superstore[Order_year],Year) -> 0
A34: North Dakota | G34: Envelopes | H34: 229.4642 | N34: Sep-2013 | O34: =SUMIFS(Superstore[Sales],Superstore[Order_month],N34,Superstore[State],State,Superstore[Category],Category,Superstore[Order_year],Year) -> 0 | P34: =SUMIFS(Superstore[Profit],Superstore[Order_month],N34,Superstore[State],State,Superstore[Category],Category,Superstore[Order_year],Year) -> 0
A35: Ohio | G35: Fasteners | H35: 4.1576 | N35: Oct-2013 | O35: =SUMIFS(Superstore[Sales],Superstore[Order_month],N35,Superstore[State],State,Superstore[Category],Category,Superstore[Order_year],Year) -> 0 | P35: =SUMIFS(Superstore[Profit],Superstore[Order_month],N35,Superstore[State],State,Superstore[Category],Category,Superstore[Order_year],Year) -> 0
A36: Oklahoma | G36: Supplies | H36: 38.7954 | N36: Nov-2013 | O36: =SUMIFS(Superstore[Sales],Superstore[Order_month],N36,Superstore[State],State,Superstore[Category],Category,Superstore[Order_year],Year) -> 0 | P36: =SUMIFS(Superstore[Profit],Superstore[Order_month],N36,Superstore[State],State,Superstore[Category],Category,Superstore[Order_year],Year) -> 0
A37: Oregon | N37: Dec-2013 | O37: =SUMIFS(Superstore[Sales],Superstore[Order_month],N37,Superstore[State],State,Superstore[Category],Category,Superstore[Order_year],Year) -> 0 | P37: =SUMIFS(Superstore[Profit],Superstore[Order_month],N37,Superstore[State],State,Superstore[Category],Category,Superstore[Order_year],Year) -> 0
A38: Pennsylvania | N38: Jan-2014 | O38: =SUMIFS(Superstore[Sales],Superstore[Order_month],N38,Superstore[State],State,Superstore[Category],Category,Superstore[Order_year],Year) -> 0 | P38: =SUMIFS(Superstore[Profit],Superstore[Order_month],N38,Superstore[State],State,Superstore[Category],Category,Superstore[Order_year],Year) -> 0
A39: Rhode Island | N39: Feb-2014 | O39: =SUMIFS(Superstore[Sales],Superstore[Order_month],N39,Superstore[State],State,Superstore[Category],Category,Superstore[Order_year],Year) -> 0 | P39: =SUMIFS(Superstore[Profit],Superstore[Order_month],N39,Superstore[State],State,Superstore[Category],Category,Superstore[Order_year],Year) -> 0
A40: South Carolina | N40: Mar-2014 | O40: =SUMIFS(Superstore[Sales],Superstore[Order_month],N40,Superstore[State],State,Superstore[Category],Category,Superstore[Order_year],Year) -> 0 | P40: =SUMIFS(Superstore[Profit],Superstore[Order_month],N40,Superstore[State],State,Superstore[Category],Category,Superstore[Order_year],Year) -> 0
...
